2025-01-19 04:37:46,135 - DEBUG - Logging setup completed.
2025-01-19 04:37:46,135 - INFO - Initializing Supabase client...
2025-01-19 04:37:46,136 - DEBUG - load_ssl_context verify=True cert=None trust_env=True http2=False
2025-01-19 04:37:46,146 - DEBUG - load_verify_locations cafile='C:\\Python_3_12\\Lib\\site-packages\\certifi\\cacert.pem'
2025-01-19 04:37:46,716 - INFO - Supabase client initialized successfully.
2025-01-19 04:37:46,716 - INFO - Starting upsert operation...
2025-01-19 04:37:46,717 - DEBUG - load_ssl_context verify=True cert=None trust_env=True http2=False
2025-01-19 04:37:46,718 - DEBUG - load_verify_locations cafile='C:\\Python_3_12\\Lib\\site-packages\\certifi\\cacert.pem'
2025-01-19 04:37:47,271 - DEBUG - connect_tcp.started host='eqthjyhskchmjtstmezk.supabase.co' port=443 local_address=None timeout=120 socket_options=None
2025-01-19 04:37:47,302 - DEBUG - connect_tcp.complete return_value=<httpcore._backends.sync.SyncStream object at 0x000001FC4786DD90>
2025-01-19 04:37:47,303 - DEBUG - start_tls.started ssl_context=<ssl.SSLContext object at 0x000001FC47960DD0> server_hostname='eqthjyhskchmjtstmezk.supabase.co' timeout=120
2025-01-19 04:37:47,317 - DEBUG - start_tls.failed exception=ConnectError(SSLCertVerificationError(1, '[SSL: CERTIFICATE_VERIFY_FAILED] certificate verify failed: self-signed certificate in certificate chain (_ssl.c:1000)'))
2025-01-19 04:37:47,318 - ERROR - An error occurred during the upsert operation.
Traceback (most recent call last):
  File "C:\Python_3_12\Lib\site-packages\httpx\_transports\default.py", line 69, in map_httpcore_exceptions
    yield
  File "C:\Python_3_12\Lib\site-packages\httpx\_transports\default.py", line 233, in handle_request
    resp = self._pool.handle_request(req)
           ^^^^^^^^^^^^^^^^^^^^^^^^^^^^^^
  File "C:\Python_3_12\Lib\site-packages\httpcore\_sync\connection_pool.py", line 216, in handle_request
    raise exc from None
  File "C:\Python_3_12\Lib\site-packages\httpcore\_sync\connection_pool.py", line 196, in handle_request
    response = connection.handle_request(
               ^^^^^^^^^^^^^^^^^^^^^^^^^^
  File "C:\Python_3_12\Lib\site-packages\httpcore\_sync\connection.py", line 99, in handle_request
    raise exc
  File "C:\Python_3_12\Lib\site-packages\httpcore\_sync\connection.py", line 76, in handle_request
    stream = self._connect(request)
             ^^^^^^^^^^^^^^^^^^^^^^
  File "C:\Python_3_12\Lib\site-packages\httpcore\_sync\connection.py", line 154, in _connect
    stream = stream.start_tls(**kwargs)
             ^^^^^^^^^^^^^^^^^^^^^^^^^^
  File "C:\Python_3_12\Lib\site-packages\httpcore\_backends\sync.py", line 152, in start_tls
    with map_exceptions(exc_map):
  File "C:\Python_3_12\Lib\contextlib.py", line 158, in __exit__
    self.gen.throw(value)
  File "C:\Python_3_12\Lib\site-packages\httpcore\_exceptions.py", line 14, in map_exceptions
    raise to_exc(exc) from exc
httpcore.ConnectError: [SSL: CERTIFICATE_VERIFY_FAILED] certificate verify failed: self-signed certificate in certificate chain (_ssl.c:1000)

The above exception was the direct cause of the following exception:

Traceback (most recent call last):
  File "C:\Users\ARYAVIN\Documents\GitHub\AI\ai\APP\FIRST-APP\SUPABASE\postgress.py", line 58, in upsert_profiles
    response = supabase.table("profiles").upsert(data).execute()
               ^^^^^^^^^^^^^^^^^^^^^^^^^^^^^^^^^^^^^^^^^^^^^^^^^
  File "C:\Python_3_12\Lib\site-packages\postgrest\_sync\request_builder.py", line 58, in execute
    r = self.session.request(
        ^^^^^^^^^^^^^^^^^^^^^
  File "C:\Python_3_12\Lib\site-packages\httpx\_client.py", line 827, in request
    return self.send(request, auth=auth, follow_redirects=follow_redirects)
           ^^^^^^^^^^^^^^^^^^^^^^^^^^^^^^^^^^^^^^^^^^^^^^^^^^^^^^^^^^^^^^^^
  File "C:\Python_3_12\Lib\site-packages\httpx\_client.py", line 914, in send
    response = self._send_handling_auth(
               ^^^^^^^^^^^^^^^^^^^^^^^^^
  File "C:\Python_3_12\Lib\site-packages\httpx\_client.py", line 942, in _send_handling_auth
    response = self._send_handling_redirects(
               ^^^^^^^^^^^^^^^^^^^^^^^^^^^^^^
  File "C:\Python_3_12\Lib\site-packages\httpx\_client.py", line 979, in _send_handling_redirects
    response = self._send_single_request(request)
               ^^^^^^^^^^^^^^^^^^^^^^^^^^^^^^^^^^
  File "C:\Python_3_12\Lib\site-packages\httpx\_client.py", line 1015, in _send_single_request
    response = transport.handle_request(request)
               ^^^^^^^^^^^^^^^^^^^^^^^^^^^^^^^^^
  File "C:\Python_3_12\Lib\site-packages\httpx\_transports\default.py", line 232, in handle_request
    with map_httpcore_exceptions():
  File "C:\Python_3_12\Lib\contextlib.py", line 158, in __exit__
    self.gen.throw(value)
  File "C:\Python_3_12\Lib\site-packages\httpx\_transports\default.py", line 86, in map_httpcore_exceptions
    raise mapped_exc(message) from exc
httpx.ConnectError: [SSL: CERTIFICATE_VERIFY_FAILED] certificate verify failed: self-signed certificate in certificate chain (_ssl.c:1000)
